2024-07-17 18:34:15,208 INFO    StreamThr :211965 [internal.py:wandb_internal():85] W&B internal server running at pid: 211965, started at: 2024-07-17 18:34:15.208103
2024-07-17 18:34:15,210 DEBUG   HandlerThread:211965 [handler.py:handle_request():158] handle_request: status
2024-07-17 18:34:15,212 INFO    WriterThread:211965 [datastore.py:open_for_write():87] open: /home/jiaqing/Desktop/DeepPurposePlusPlus/wandb/run-20240717_183415-7kmrru79/run-7kmrru79.wandb
2024-07-17 18:34:15,213 DEBUG   SenderThread:211965 [sender.py:send():379] send: header
2024-07-17 18:34:15,245 DEBUG   SenderThread:211965 [sender.py:send():379] send: run
2024-07-17 18:34:20,246 DEBUG   HandlerThread:211965 [handler.py:handle_request():158] handle_request: keepalive
2024-07-17 18:34:25,247 DEBUG   HandlerThread:211965 [handler.py:handle_request():158] handle_request: keepalive
2024-07-17 18:34:30,248 DEBUG   HandlerThread:211965 [handler.py:handle_request():158] handle_request: keepalive
2024-07-17 18:34:35,249 DEBUG   HandlerThread:211965 [handler.py:handle_request():158] handle_request: keepalive
2024-07-17 18:34:40,250 DEBUG   HandlerThread:211965 [handler.py:handle_request():158] handle_request: keepalive
2024-07-17 18:34:45,251 DEBUG   HandlerThread:211965 [handler.py:handle_request():158] handle_request: keepalive
2024-07-17 18:34:50,252 DEBUG   HandlerThread:211965 [handler.py:handle_request():158] handle_request: keepalive
2024-07-17 18:34:55,253 DEBUG   HandlerThread:211965 [handler.py:handle_request():158] handle_request: keepalive
2024-07-17 18:35:00,254 DEBUG   HandlerThread:211965 [handler.py:handle_request():158] handle_request: keepalive
2024-07-17 18:35:05,255 DEBUG   HandlerThread:211965 [handler.py:handle_request():158] handle_request: keepalive
2024-07-17 18:35:10,256 DEBUG   HandlerThread:211965 [handler.py:handle_request():158] handle_request: keepalive
2024-07-17 18:35:15,257 DEBUG   HandlerThread:211965 [handler.py:handle_request():158] handle_request: keepalive
2024-07-17 18:35:19,581 INFO    SenderThread:211965 [retry.py:__call__():172] Retry attempt failed:
Traceback (most recent call last):
  File "/home/jiaqing/miniconda3/envs/graph/lib/python3.9/site-packages/urllib3/connectionpool.py", line 537, in _make_request
    response = conn.getresponse()
  File "/home/jiaqing/miniconda3/envs/graph/lib/python3.9/site-packages/urllib3/connection.py", line 466, in getresponse
    httplib_response = super().getresponse()
  File "/home/jiaqing/miniconda3/envs/graph/lib/python3.9/http/client.py", line 1377, in getresponse
    response.begin()
  File "/home/jiaqing/miniconda3/envs/graph/lib/python3.9/http/client.py", line 320, in begin
    version, status, reason = self._read_status()
  File "/home/jiaqing/miniconda3/envs/graph/lib/python3.9/http/client.py", line 281, in _read_status
    line = str(self.fp.readline(_MAXLINE + 1), "iso-8859-1")
  File "/home/jiaqing/miniconda3/envs/graph/lib/python3.9/socket.py", line 704, in readinto
    return self._sock.recv_into(b)
  File "/home/jiaqing/miniconda3/envs/graph/lib/python3.9/ssl.py", line 1275, in recv_into
    return self.read(nbytes, buffer)
  File "/home/jiaqing/miniconda3/envs/graph/lib/python3.9/ssl.py", line 1133, in read
    return self._sslobj.read(len, buffer)
socket.timeout: The read operation timed out

The above exception was the direct cause of the following exception:

Traceback (most recent call last):
  File "/home/jiaqing/miniconda3/envs/graph/lib/python3.9/site-packages/requests/adapters.py", line 589, in send
    resp = conn.urlopen(
  File "/home/jiaqing/miniconda3/envs/graph/lib/python3.9/site-packages/urllib3/connectionpool.py", line 847, in urlopen
    retries = retries.increment(
  File "/home/jiaqing/miniconda3/envs/graph/lib/python3.9/site-packages/urllib3/util/retry.py", line 470, in increment
    raise reraise(type(error), error, _stacktrace)
  File "/home/jiaqing/miniconda3/envs/graph/lib/python3.9/site-packages/urllib3/util/util.py", line 39, in reraise
    raise value
  File "/home/jiaqing/miniconda3/envs/graph/lib/python3.9/site-packages/urllib3/connectionpool.py", line 793, in urlopen
    response = self._make_request(
  File "/home/jiaqing/miniconda3/envs/graph/lib/python3.9/site-packages/urllib3/connectionpool.py", line 539, in _make_request
    self._raise_timeout(err=e, url=url, timeout_value=read_timeout)
  File "/home/jiaqing/miniconda3/envs/graph/lib/python3.9/site-packages/urllib3/connectionpool.py", line 370, in _raise_timeout
    raise ReadTimeoutError(
urllib3.exceptions.ReadTimeoutError: HTTPSConnectionPool(host='api.wandb.ai', port=443): Read timed out. (read timeout=20)

During handling of the above exception, another exception occurred:

Traceback (most recent call last):
  File "/home/jiaqing/miniconda3/envs/graph/lib/python3.9/site-packages/wandb/sdk/lib/retry.py", line 131, in __call__
    result = self._call_fn(*args, **kwargs)
  File "/home/jiaqing/miniconda3/envs/graph/lib/python3.9/site-packages/wandb/sdk/internal/internal_api.py", line 345, in execute
    return self.client.execute(*args, **kwargs)  # type: ignore
  File "/home/jiaqing/miniconda3/envs/graph/lib/python3.9/site-packages/wandb/vendor/gql-0.2.0/wandb_gql/client.py", line 52, in execute
    result = self._get_result(document, *args, **kwargs)
  File "/home/jiaqing/miniconda3/envs/graph/lib/python3.9/site-packages/wandb/vendor/gql-0.2.0/wandb_gql/client.py", line 60, in _get_result
    return self.transport.execute(document, *args, **kwargs)
  File "/home/jiaqing/miniconda3/envs/graph/lib/python3.9/site-packages/wandb/sdk/lib/gql_request.py", line 58, in execute
    request = self.session.post(self.url, **post_args)
  File "/home/jiaqing/miniconda3/envs/graph/lib/python3.9/site-packages/requests/sessions.py", line 637, in post
    return self.request("POST", url, data=data, json=json, **kwargs)
  File "/home/jiaqing/miniconda3/envs/graph/lib/python3.9/site-packages/requests/sessions.py", line 589, in request
    resp = self.send(prep, **send_kwargs)
  File "/home/jiaqing/miniconda3/envs/graph/lib/python3.9/site-packages/requests/sessions.py", line 703, in send
    r = adapter.send(request, **kwargs)
  File "/home/jiaqing/miniconda3/envs/graph/lib/python3.9/site-packages/requests/adapters.py", line 635, in send
    raise ReadTimeout(e, request=request)
requests.exceptions.ReadTimeout: HTTPSConnectionPool(host='api.wandb.ai', port=443): Read timed out. (read timeout=20)
2024-07-17 18:35:20,259 DEBUG   HandlerThread:211965 [handler.py:handle_request():158] handle_request: keepalive
2024-07-17 18:35:25,260 DEBUG   HandlerThread:211965 [handler.py:handle_request():158] handle_request: keepalive
2024-07-17 18:35:30,261 DEBUG   HandlerThread:211965 [handler.py:handle_request():158] handle_request: keepalive
2024-07-17 18:35:35,262 DEBUG   HandlerThread:211965 [handler.py:handle_request():158] handle_request: keepalive
2024-07-17 18:35:40,263 DEBUG   HandlerThread:211965 [handler.py:handle_request():158] handle_request: keepalive
2024-07-17 18:35:45,263 DEBUG   HandlerThread:211965 [handler.py:handle_request():158] handle_request: cancel
2024-07-17 18:35:45,264 DEBUG   HandlerThread:211965 [handler.py:handle_request():158] handle_request: cancel
2024-07-17 18:35:46,051 DEBUG   HandlerThread:211965 [handler.py:handle_request():158] handle_request: shutdown
2024-07-17 18:35:46,051 INFO    HandlerThread:211965 [handler.py:finish():882] shutting down handler
2024-07-17 18:35:46,264 INFO    WriterThread:211965 [datastore.py:close():296] close: /home/jiaqing/Desktop/DeepPurposePlusPlus/wandb/run-20240717_183415-7kmrru79/run-7kmrru79.wandb
2024-07-17 18:36:00,971 DEBUG   SenderThread:211965 [sender.py:send():388] Record cancelled: run
2024-07-17 18:36:00,971 INFO    SenderThread:211965 [sender.py:finish():1608] shutting down sender
