2024-07-17 18:34:15,204 INFO    MainThread:211931 [wandb_setup.py:_flush():76] Current SDK version is 0.17.4
2024-07-17 18:34:15,204 INFO    MainThread:211931 [wandb_setup.py:_flush():76] Configure stats pid to 211931
2024-07-17 18:34:15,204 INFO    MainThread:211931 [wandb_setup.py:_flush():76] Loading settings from /home/jiaqing/.config/wandb/settings
2024-07-17 18:34:15,204 INFO    MainThread:211931 [wandb_setup.py:_flush():76] Loading settings from /home/jiaqing/Desktop/DeepPurposePlusPlus/wandb/settings
2024-07-17 18:34:15,204 INFO    MainThread:211931 [wandb_setup.py:_flush():76] Loading settings from environment variables: {}
2024-07-17 18:34:15,204 INFO    MainThread:211931 [wandb_setup.py:_flush():76] Applying setup settings: {'_disable_service': False}
2024-07-17 18:34:15,204 INFO    MainThread:211931 [wandb_setup.py:_flush():76] Inferring run settings from compute environment: {'program_relpath': 'train/beta.py', 'program_abspath': '/home/jiaqing/Desktop/DeepPurposePlusPlus/train/beta.py', 'program': '/home/jiaqing/Desktop/DeepPurposePlusPlus/train/beta.py'}
2024-07-17 18:34:15,205 INFO    MainThread:211931 [wandb_setup.py:_flush():76] Applying login settings: {}
2024-07-17 18:34:15,205 INFO    MainThread:211931 [wandb_init.py:_log_setup():529] Logging user logs to /home/jiaqing/Desktop/DeepPurposePlusPlus/wandb/run-20240717_183415-7kmrru79/logs/debug.log
2024-07-17 18:34:15,205 INFO    MainThread:211931 [wandb_init.py:_log_setup():530] Logging internal logs to /home/jiaqing/Desktop/DeepPurposePlusPlus/wandb/run-20240717_183415-7kmrru79/logs/debug-internal.log
2024-07-17 18:34:15,205 INFO    MainThread:211931 [wandb_init.py:init():569] calling init triggers
2024-07-17 18:34:15,205 INFO    MainThread:211931 [wandb_init.py:init():576] wandb.init called with sweep_config: {}
config: {}
2024-07-17 18:34:15,205 INFO    MainThread:211931 [wandb_init.py:init():619] starting backend
2024-07-17 18:34:15,205 INFO    MainThread:211931 [wandb_init.py:init():623] setting up manager
2024-07-17 18:34:15,206 INFO    MainThread:211931 [backend.py:_multiprocessing_setup():105] multiprocessing start_methods=fork,spawn,forkserver, using: spawn
2024-07-17 18:34:15,208 INFO    MainThread:211931 [wandb_init.py:init():631] backend started and connected
2024-07-17 18:34:15,212 INFO    MainThread:211931 [wandb_init.py:init():720] updated telemetry
2024-07-17 18:34:15,244 INFO    MainThread:211931 [wandb_init.py:init():753] communicating run to backend with 90.0 second timeout
2024-07-17 18:35:16,569 INFO    Thread-1  :211931 [retry.py:__call__():172] Retry attempt failed:
Traceback (most recent call last):
  File "/home/jiaqing/miniconda3/envs/graph/lib/python3.9/site-packages/urllib3/connectionpool.py", line 537, in _make_request
    response = conn.getresponse()
  File "/home/jiaqing/miniconda3/envs/graph/lib/python3.9/site-packages/urllib3/connection.py", line 466, in getresponse
    httplib_response = super().getresponse()
  File "/home/jiaqing/miniconda3/envs/graph/lib/python3.9/http/client.py", line 1377, in getresponse
    response.begin()
  File "/home/jiaqing/miniconda3/envs/graph/lib/python3.9/http/client.py", line 320, in begin
    version, status, reason = self._read_status()
  File "/home/jiaqing/miniconda3/envs/graph/lib/python3.9/http/client.py", line 281, in _read_status
    line = str(self.fp.readline(_MAXLINE + 1), "iso-8859-1")
  File "/home/jiaqing/miniconda3/envs/graph/lib/python3.9/socket.py", line 704, in readinto
    return self._sock.recv_into(b)
  File "/home/jiaqing/miniconda3/envs/graph/lib/python3.9/ssl.py", line 1275, in recv_into
    return self.read(nbytes, buffer)
  File "/home/jiaqing/miniconda3/envs/graph/lib/python3.9/ssl.py", line 1133, in read
    return self._sslobj.read(len, buffer)
socket.timeout: The read operation timed out

The above exception was the direct cause of the following exception:

Traceback (most recent call last):
  File "/home/jiaqing/miniconda3/envs/graph/lib/python3.9/site-packages/requests/adapters.py", line 589, in send
    resp = conn.urlopen(
  File "/home/jiaqing/miniconda3/envs/graph/lib/python3.9/site-packages/urllib3/connectionpool.py", line 847, in urlopen
    retries = retries.increment(
  File "/home/jiaqing/miniconda3/envs/graph/lib/python3.9/site-packages/urllib3/util/retry.py", line 470, in increment
    raise reraise(type(error), error, _stacktrace)
  File "/home/jiaqing/miniconda3/envs/graph/lib/python3.9/site-packages/urllib3/util/util.py", line 39, in reraise
    raise value
  File "/home/jiaqing/miniconda3/envs/graph/lib/python3.9/site-packages/urllib3/connectionpool.py", line 793, in urlopen
    response = self._make_request(
  File "/home/jiaqing/miniconda3/envs/graph/lib/python3.9/site-packages/urllib3/connectionpool.py", line 539, in _make_request
    self._raise_timeout(err=e, url=url, timeout_value=read_timeout)
  File "/home/jiaqing/miniconda3/envs/graph/lib/python3.9/site-packages/urllib3/connectionpool.py", line 370, in _raise_timeout
    raise ReadTimeoutError(
urllib3.exceptions.ReadTimeoutError: HTTPSConnectionPool(host='api.wandb.ai', port=443): Read timed out. (read timeout=20)

During handling of the above exception, another exception occurred:

Traceback (most recent call last):
  File "/home/jiaqing/miniconda3/envs/graph/lib/python3.9/site-packages/wandb/sdk/lib/retry.py", line 131, in __call__
    result = self._call_fn(*args, **kwargs)
  File "/home/jiaqing/miniconda3/envs/graph/lib/python3.9/site-packages/wandb/sdk/internal/internal_api.py", line 345, in execute
    return self.client.execute(*args, **kwargs)  # type: ignore
  File "/home/jiaqing/miniconda3/envs/graph/lib/python3.9/site-packages/wandb/vendor/gql-0.2.0/wandb_gql/client.py", line 52, in execute
    result = self._get_result(document, *args, **kwargs)
  File "/home/jiaqing/miniconda3/envs/graph/lib/python3.9/site-packages/wandb/vendor/gql-0.2.0/wandb_gql/client.py", line 60, in _get_result
    return self.transport.execute(document, *args, **kwargs)
  File "/home/jiaqing/miniconda3/envs/graph/lib/python3.9/site-packages/wandb/sdk/lib/gql_request.py", line 58, in execute
    request = self.session.post(self.url, **post_args)
  File "/home/jiaqing/miniconda3/envs/graph/lib/python3.9/site-packages/requests/sessions.py", line 637, in post
    return self.request("POST", url, data=data, json=json, **kwargs)
  File "/home/jiaqing/miniconda3/envs/graph/lib/python3.9/site-packages/requests/sessions.py", line 589, in request
    resp = self.send(prep, **send_kwargs)
  File "/home/jiaqing/miniconda3/envs/graph/lib/python3.9/site-packages/requests/sessions.py", line 703, in send
    r = adapter.send(request, **kwargs)
  File "/home/jiaqing/miniconda3/envs/graph/lib/python3.9/site-packages/requests/adapters.py", line 635, in send
    raise ReadTimeout(e, request=request)
requests.exceptions.ReadTimeout: HTTPSConnectionPool(host='api.wandb.ai', port=443): Read timed out. (read timeout=20)
2024-07-17 18:35:45,263 ERROR   MainThread:211931 [wandb_init.py:init():779] encountered error: Run initialization has timed out after 90.0 sec. 
Please refer to the documentation for additional information: https://docs.wandb.ai/guides/track/tracking-faq#initstarterror-error-communicating-with-wandb-process-
2024-07-17 18:35:45,264 ERROR   MainThread:211931 [wandb_init.py:init():1191] error in wandb.init()
Traceback (most recent call last):
  File "/home/jiaqing/miniconda3/envs/graph/lib/python3.9/site-packages/wandb/sdk/wandb_init.py", line 1181, in init
    return wi.init()
  File "/home/jiaqing/miniconda3/envs/graph/lib/python3.9/site-packages/wandb/sdk/wandb_init.py", line 785, in init
    raise error
wandb.errors.CommError: Run initialization has timed out after 90.0 sec. 
Please refer to the documentation for additional information: https://docs.wandb.ai/guides/track/tracking-faq#initstarterror-error-communicating-with-wandb-process-
2024-07-17 18:36:00,972 WARNING MsgRouterThr:211931 [router.py:message_loop():77] message_loop has been closed
