2024-07-17 18:53:08,568 INFO    StreamThr :212444 [internal.py:wandb_internal():85] W&B internal server running at pid: 212444, started at: 2024-07-17 18:53:08.567496
2024-07-17 18:53:08,570 DEBUG   HandlerThread:212444 [handler.py:handle_request():158] handle_request: status
2024-07-17 18:53:08,572 INFO    WriterThread:212444 [datastore.py:open_for_write():87] open: /home/jiaqing/Desktop/DeepPurposePlusPlus/wandb/run-20240717_185308-tcdhvm14/run-tcdhvm14.wandb
2024-07-17 18:53:08,572 DEBUG   SenderThread:212444 [sender.py:send():379] send: header
2024-07-17 18:53:08,606 DEBUG   SenderThread:212444 [sender.py:send():379] send: run
2024-07-17 18:53:09,554 ERROR   SenderThread:212444 [internal_api.py:execute():349] 500 response executing GraphQL.
2024-07-17 18:53:09,554 ERROR   SenderThread:212444 [internal_api.py:execute():350] {"error":"An internal error occurred. Please contact support."}
2024-07-17 18:53:10,998 ERROR   SenderThread:212444 [internal_api.py:execute():349] 500 response executing GraphQL.
2024-07-17 18:53:10,999 ERROR   SenderThread:212444 [internal_api.py:execute():350] {"error":"An internal error occurred. Please contact support."}
2024-07-17 18:53:13,595 ERROR   SenderThread:212444 [internal_api.py:execute():349] 500 response executing GraphQL.
2024-07-17 18:53:13,595 ERROR   SenderThread:212444 [internal_api.py:execute():350] {"error":"An internal error occurred. Please contact support."}
2024-07-17 18:53:13,596 INFO    SenderThread:212444 [retry.py:__call__():172] Retry attempt failed:
Traceback (most recent call last):
  File "/home/jiaqing/miniconda3/envs/graph/lib/python3.9/site-packages/wandb/sdk/lib/retry.py", line 131, in __call__
    result = self._call_fn(*args, **kwargs)
  File "/home/jiaqing/miniconda3/envs/graph/lib/python3.9/site-packages/wandb/sdk/internal/internal_api.py", line 345, in execute
    return self.client.execute(*args, **kwargs)  # type: ignore
  File "/home/jiaqing/miniconda3/envs/graph/lib/python3.9/site-packages/wandb/vendor/gql-0.2.0/wandb_gql/client.py", line 52, in execute
    result = self._get_result(document, *args, **kwargs)
  File "/home/jiaqing/miniconda3/envs/graph/lib/python3.9/site-packages/wandb/vendor/gql-0.2.0/wandb_gql/client.py", line 60, in _get_result
    return self.transport.execute(document, *args, **kwargs)
  File "/home/jiaqing/miniconda3/envs/graph/lib/python3.9/site-packages/wandb/sdk/lib/gql_request.py", line 59, in execute
    request.raise_for_status()
  File "/home/jiaqing/miniconda3/envs/graph/lib/python3.9/site-packages/requests/models.py", line 1024, in raise_for_status
    raise HTTPError(http_error_msg, response=self)
requests.exceptions.HTTPError: 500 Server Error: Internal Server Error for url: https://api.wandb.ai/graphql
2024-07-17 18:53:13,608 DEBUG   HandlerThread:212444 [handler.py:handle_request():158] handle_request: keepalive
2024-07-17 18:53:18,608 DEBUG   HandlerThread:212444 [handler.py:handle_request():158] handle_request: keepalive
2024-07-17 18:53:18,665 ERROR   SenderThread:212444 [internal_api.py:execute():349] 500 response executing GraphQL.
2024-07-17 18:53:18,665 ERROR   SenderThread:212444 [internal_api.py:execute():350] {"error":"An internal error occurred. Please contact support."}
2024-07-17 18:53:19,602 DEBUG   HandlerThread:212444 [handler.py:handle_request():158] handle_request: shutdown
2024-07-17 18:53:19,602 INFO    HandlerThread:212444 [handler.py:finish():882] shutting down handler
2024-07-17 18:53:19,607 INFO    WriterThread:212444 [datastore.py:close():296] close: /home/jiaqing/Desktop/DeepPurposePlusPlus/wandb/run-20240717_185308-tcdhvm14/run-tcdhvm14.wandb
2024-07-17 18:53:28,077 ERROR   SenderThread:212444 [internal_api.py:execute():349] 500 response executing GraphQL.
2024-07-17 18:53:28,078 ERROR   SenderThread:212444 [internal_api.py:execute():350] {"error":"An internal error occurred. Please contact support."}
2024-07-17 18:53:47,738 ERROR   SenderThread:212444 [internal_api.py:execute():349] 500 response executing GraphQL.
2024-07-17 18:53:47,738 ERROR   SenderThread:212444 [internal_api.py:execute():350] {"error":"An internal error occurred. Please contact support."}
2024-07-17 18:54:26,378 INFO    SenderThread:212444 [dir_watcher.py:__init__():211] watching files in: /home/jiaqing/Desktop/DeepPurposePlusPlus/wandb/run-20240717_185308-tcdhvm14/files
2024-07-17 18:54:26,378 INFO    SenderThread:212444 [sender.py:_start_run_threads():1188] run started: tcdhvm14 with start time 1721213588.567598
2024-07-17 18:54:26,378 INFO    SenderThread:212444 [sender.py:finish():1608] shutting down sender
2024-07-17 18:54:26,378 INFO    SenderThread:212444 [dir_watcher.py:finish():358] shutting down directory watcher
2024-07-17 18:54:27,378 INFO    SenderThread:212444 [dir_watcher.py:finish():388] scan: /home/jiaqing/Desktop/DeepPurposePlusPlus/wandb/run-20240717_185308-tcdhvm14/files
2024-07-17 18:54:27,379 INFO    SenderThread:212444 [dir_watcher.py:finish():402] scan save: /home/jiaqing/Desktop/DeepPurposePlusPlus/wandb/run-20240717_185308-tcdhvm14/files/config.yaml config.yaml
2024-07-17 18:54:27,379 INFO    SenderThread:212444 [file_pusher.py:finish():169] shutting down file pusher
2024-07-17 18:54:27,379 INFO    SenderThread:212444 [file_pusher.py:join():175] waiting for file pusher
2024-07-17 18:54:29,124 INFO    wandb-upload_0:212444 [upload_job.py:push():130] Uploaded file /home/jiaqing/Desktop/DeepPurposePlusPlus/wandb/run-20240717_185308-tcdhvm14/files/config.yaml
2024-07-17 18:54:29,381 INFO    SenderThread:212444 [file_stream.py:finish():601] file stream finish called
2024-07-17 18:54:30,342 INFO    SenderThread:212444 [file_stream.py:finish():605] file stream finish is done
