























100%|█████████████████████████████████████████████████████████████████████████████████████████████████████████████████████████████████████████████████████████████| 2421/2421 [00:48<00:00, 49.97it/s]

100%|███████████████████████████████████████████████████████████████████████████████████████████████████████████████████████████████████████████████████████████████| 203/203 [00:05<00:00, 36.04it/s]



100%|███████████████████████████████████████████████████████████████████████████████████████████████████████████████████████████████████████████████████████████████| 326/326 [00:05<00:00, 55.92it/s]
Protein Protein Interaction Prediction Mode...
in total: 2421 protein-protein pairs
encoding protein...
unique target sequence: 546
encoding protein...
unique target sequence: 1581
Done.
Protein Protein Interaction Prediction Mode...
in total: 203 protein-protein pairs
encoding protein...
unique target sequence: 74
encoding protein...
unique target sequence: 138
Done.
Protein Protein Interaction Prediction Mode...
in total: 326 protein-protein pairs
encoding protein...
unique target sequence: 60
encoding protein...
unique target sequence: 283
Done.
Let's use 1 GPU!
--- Data Preparation ---
--- Go for Training ---
Traceback (most recent call last):
  File "E:\DeepPurposePlusPlus\train\ppi_affinity.py", line 82, in <module>
    model.train(train, val, test)
  File "E:\DeepPurposePlusPlus\ProB\PPI.py", line 268, in train
    for i, (v_d, v_p, label) in enumerate(training_generator):
  File "E:\anaconda3\envs\graph\lib\site-packages\torch\utils\data\dataloader.py", line 631, in __next__
    data = self._next_data()
  File "E:\anaconda3\envs\graph\lib\site-packages\torch\utils\data\dataloader.py", line 1346, in _next_data
    return self._process_data(data)
  File "E:\anaconda3\envs\graph\lib\site-packages\torch\utils\data\dataloader.py", line 1372, in _process_data
    data.reraise()
  File "E:\anaconda3\envs\graph\lib\site-packages\torch\_utils.py", line 705, in reraise
    raise exception
AttributeError: Caught AttributeError in DataLoader worker process 0.
Original Traceback (most recent call last):
  File "E:\anaconda3\envs\graph\lib\site-packages\torch\utils\data\_utils\worker.py", line 308, in _worker_loop
    data = fetcher.fetch(index)  # type: ignore[possibly-undefined]
  File "E:\anaconda3\envs\graph\lib\site-packages\torch\utils\data\_utils\fetch.py", line 54, in fetch
    return self.collate_fn(data)
  File "E:\DeepPurposePlusPlus\ProB\PPI.py", line 63, in dgl_collate_func
    x1 = dgl.batch(x1)
  File "E:\anaconda3\envs\graph\lib\site-packages\dgl\batch.py", line 164, in batch
    if any(g.is_block for g in graphs):
  File "E:\anaconda3\envs\graph\lib\site-packages\dgl\batch.py", line 164, in <genexpr>
    if any(g.is_block for g in graphs):
AttributeError: 'str' object has no attribute 'is_block'