



























100%|█████████████████████████████████████████████████████████████████████████████████████████████████████████████████████████████████████████████████████████████| 2421/2421 [00:58<00:00, 41.69it/s]


100%|███████████████████████████████████████████████████████████████████████████████████████████████████████████████████████████████████████████████████████████████| 203/203 [00:05<00:00, 35.85it/s]



100%|███████████████████████████████████████████████████████████████████████████████████████████████████████████████████████████████████████████████████████████████| 326/326 [00:06<00:00, 53.59it/s]
Protein Protein Interaction Prediction Mode...
in total: 2421 protein-protein pairs
encoding protein...
unique target sequence: 546
encoding protein...
unique target sequence: 1581
Done.
Protein Protein Interaction Prediction Mode...
in total: 203 protein-protein pairs
encoding protein...
unique target sequence: 74
encoding protein...
unique target sequence: 138
Done.
Protein Protein Interaction Prediction Mode...
in total: 326 protein-protein pairs
encoding protein...
unique target sequence: 60
encoding protein...
unique target sequence: 283
Done.
Let's use 1 GPU!
--- Data Preparation ---
--- Go for Training ---
Traceback (most recent call last):
  File "E:\DeepPurposePlusPlus\train\ppi_affinity.py", line 82, in <module>
    model.train(train, val, test)
  File "E:\DeepPurposePlusPlus\ProB\PPI.py", line 240, in train
    for i, (v_d, v_p, label) in enumerate(training_generator):
  File "E:\anaconda3\envs\graph\lib\site-packages\torch\utils\data\dataloader.py", line 631, in __next__
    data = self._next_data()
  File "E:\anaconda3\envs\graph\lib\site-packages\torch\utils\data\dataloader.py", line 1346, in _next_data
    return self._process_data(data)
  File "E:\anaconda3\envs\graph\lib\site-packages\torch\utils\data\dataloader.py", line 1372, in _process_data
    data.reraise()
  File "E:\anaconda3\envs\graph\lib\site-packages\torch\_utils.py", line 705, in reraise
    raise exception
TypeError: Caught TypeError in DataLoader worker process 0.
Original Traceback (most recent call last):
  File "E:\anaconda3\envs\graph\lib\site-packages\torch\utils\data\_utils\worker.py", line 308, in _worker_loop
    data = fetcher.fetch(index)  # type: ignore[possibly-undefined]
  File "E:\anaconda3\envs\graph\lib\site-packages\torch\utils\data\_utils\fetch.py", line 54, in fetch
    return self.collate_fn(data)
  File "E:\anaconda3\envs\graph\lib\site-packages\torch\utils\data\_utils\collate.py", line 316, in default_collate
    return collate(batch, collate_fn_map=default_collate_fn_map)
  File "E:\anaconda3\envs\graph\lib\site-packages\torch\utils\data\_utils\collate.py", line 173, in collate
    return [collate(samples, collate_fn_map=collate_fn_map) for samples in transposed]  # Backwards compatibility.
  File "E:\anaconda3\envs\graph\lib\site-packages\torch\utils\data\_utils\collate.py", line 173, in <listcomp>
    return [collate(samples, collate_fn_map=collate_fn_map) for samples in transposed]  # Backwards compatibility.
  File "E:\anaconda3\envs\graph\lib\site-packages\torch\utils\data\_utils\collate.py", line 191, in collate
    raise TypeError(default_collate_err_msg_format.format(elem_type))
TypeError: default_collate: batch must contain tensors, numpy arrays, numbers, dicts or lists; found <class 'dgl.heterograph.DGLGraph'>